Workbook

Sheet Total
A2: PLAYER | B2: G | C2: PA | D2: AB | E2: RUNS | F2: HITS | G2: RBI | H2: 1B | I2: 2B | J2: 3B | K2: HR | L2: SB | M2: BB | N2: K | O2: HBP | P2: SF | Q2: SH | R2: TB | S2: AVG | T2: OBP | U2: SLG | V2: OPS | W2: Runs Created | X2: BB% | Y2: K% | Z2: BB/K | AA2: AB/HR | AB2: wOBA | AC2: LOB | AD2: CS | AE2: SB% | AF2: ERRORS | AG2: BAbip | AH2: ISO | AI2: PwrSpd
A3: Adam Holstein (Jr) | B3: ='Regular Season'!B3+Postseason!B3 -> 5 | C3: ='Regular Season'!C3+Postseason!C3 -> 7 | D3: ='Regular Season'!D3+Postseason!D3 -> 5 | E3: ='Regular Season'!E3+Postseason!E3 -> 3 | F3: ='Regular Season'!F3+Postseason!F3 -> 0 | G3: ='Regular Season'!G3+Postseason!G3 -> 0 | H3: ='Regular Season'!H3+Postseason!H3 -> 0 | I3: ='Regular Season'!I3+Postseason!I3 -> 0 | ... R3: ='Regular Season'!R3+Postseason!R3 -> 0 | S3: =if(D3=0,"-", F3/D3) -> 0 | T3: =if(C3=0, "-", (F3+M3+O3)/(D3+M3+O3+P3)) -> 0.28571429 | U3: =iferror(if(C3=0, "-", R3/D3), 0) -> 0 | V3: =if(T3="-", "-", T3+U3) -> 0.28571429 | W3: =if(C3=0,"-", ((F3+M3)*R3)/(D3+M3)) -> 0 | X3: =if(C3=0, "-", M3/C3) -> 0.14285714 | Y3: =if(C3=0, "-", N3/C3) -> 0.28571429 | Z3: =ifs(Y3="-", "-", Y3=0, "0", Y3<>0, M3/N3) -> 0.5 | AA3: =IF(K3=0, "-", D3/K3) -> - | AB3: =if(C3=0, "-", ((0.69*M3)+(0.72*O3)+(0.88*H3)+(1.24*I3)+(1.57*J3)+(2*K3))/(D3+M3+O3+P3)) -> 0.20142857 | AC3: =if(C3=0, "-",'Regular Season'!AC3+Postseason!AC3) -> 6 | AD3: ='Regular Season'!AD3+Postseason!AD3 -> 0 | AE3: =if(L3=0, "-", L3/(L3+AD3)) -> - | AF3: ='Regular Season'!AF3+Postseason!AF3 -> 0 | AG3: =iferror((F3-K3)/(D3-K3-N3+P3), "-") -> 0 | AH3: =iferror((R3-F3)/D3, "-") -> 0 | AI3: =iferror(2*(K3*L3)/(K3+L3), "-") -> -
A4: Adam Maybury (Jr) | B4: ='Regular Season'!B4+Postseason!B4 -> 10 | C4: ='Regular Season'!C4+Postseason!C4 -> 18 | D4: ='Regular Season'!D4+Postseason!D4 -> 13 | E4: ='Regular Season'!E4+Postseason!E4 -> 6 | F4: ='Regular Season'!F4+Postseason!F4 -> 2 | G4: ='Regular Season'!G4+Postseason!G4 -> 1 | H4: ='Regular Season'!H4+Postseason!H4 -> 2 | I4: ='Regular Season'!I4+Postseason!I4 -> 0 | ... R4: ='Regular Season'!R4+Postseason!R4 -> 2 | S4: =if(D4=0,"-", F4/D4) -> 0.15384615 | T4: =if(C4=0, "-", (F4+M4+O4)/(D4+M4+O4+P4)) -> 0.38888889 | U4: =iferror(if(C4=0, "-", R4/D4), 0) -> 0.15384615 | V4: =if(T4="-", "-", T4+U4) -> 0.54273504 | W4: =if(C4=0,"-", ((F4+M4)*R4)/(D4+M4)) -> 0.77777778 | X4: =if(C4=0, "-", M4/C4) -> 0.27777778 | Y4: =if(C4=0, "-", N4/C4) -> 0.16666667 | Z4: =ifs(Y4="-", "-", Y4=0, "0", Y4<>0, M4/N4) -> 1.6666667 | AA4: =IF(K4=0, "-", D4/K4) -> - | AB4: =if(C4=0, "-", ((0.69*M4)+(0.72*O4)+(0.88*H4)+(1.24*I4)+(1.57*J4)+(2*K4))/(D4+M4+O4+P4)) -> 0.28944444 | AC4: =if(D4=0, "-",'Regular Season'!AC4+Postseason!AC4) -> 2 | AD4: ='Regular Season'!AD4+Postseason!AD4 -> 0 | AE4: =if(L4=0, "-", L4/(L4+AD4)) -> 1 | AF4: ='Regular Season'!AF4+Postseason!AF4 -> 0 | AG4: =iferror((F4-K4)/(D4-K4-N4+P4), "-") -> 0.2 | AH4: =iferror((R4-F4)/D4, "-") -> 0 | AI4: =iferror(2*(K4*L4)/(K4+L4), "-") -> 0
A5: Brody Foltz (Sr) | B5: ='Regular Season'!B5+Postseason!B5 -> 6 | C5: ='Regular Season'!C5+Postseason!C5 -> 7 | D5: ='Regular Season'!D5+Postseason!D5 -> 3 | E5: ='Regular Season'!E5+Postseason!E5 -> 1 | F5: ='Regular Season'!F5+Postseason!F5 -> 1 | G5: ='Regular Season'!G5+Postseason!G5 -> 2 | H5: ='Regular Season'!H5+Postseason!H5 -> 1 | I5: ='Regular Season'!I5+Postseason!I5 -> 0 | ... R5: ='Regular Season'!R5+Postseason!R5 -> 1 | S5: =if(D5=0,"-", F5/D5) -> 0.33333333 | T5: =if(C5=0, "-", (F5+M5+O5)/(D5+M5+O5+P5)) -> 0.71428571 | U5: =iferror(if(C5=0, "-", R5/D5), 0) -> 0.33333333 | V5: =if(T5="-", "-", T5+U5) -> 1.047619 | W5: =if(C5=0,"-", ((F5+M5)*R5)/(D5+M5)) -> 0.66666667 | X5: =if(C5=0, "-", M5/C5) -> 0.42857143 | Y5: =if(C5=0, "-", N5/C5) -> 0.14285714 | Z5: =ifs(Y5="-", "-", Y5=0, "0", Y5<>0, M5/N5) -> 3 | AA5: =IF(K5=0, "-", D5/K5) -> - | AB5: =if(C5=0, "-", ((0.69*M5)+(0.72*O5)+(0.88*H5)+(1.24*I5)+(1.57*J5)+(2*K5))/(D5+M5+O5+P5)) -> 0.52428571 | AC5: =if(D5=0, "-",'Regular Season'!AC5+Postseason!AC5) -> 1 | AD5: ='Regular Season'!AD5+Postseason!AD5 -> 0 | AE5: =if(L5=0, "-", L5/(L5+AD5)) -> - | AF5: ='Regular Season'!AF5+Postseason!AF5 -> 0 | AG5: =iferror((F5-K5)/(D5-K5-N5+P5), "-") -> 0.5 | AH5: =iferror((R5-F5)/D5, "-") -> 0 | AI5: =iferror(2*(K5*L5)/(K5+L5), "-") -> -
A6: Carter Christenson (Sr) | B6: ='Regular Season'!B6+Postseason!B6 -> 28 | C6: ='Regular Season'!C6+Postseason!C6 -> 99 | D6: ='Regular Season'!D6+Postseason!D6 -> 77 | E6: ='Regular Season'!E6+Postseason!E6 -> 27 | F6: ='Regular Season'!F6+Postseason!F6 -> 30 | G6: ='Regular Season'!G6+Postseason!G6 -> 25 | H6: ='Regular Season'!H6+Postseason!H6 -> 20 | I6: ='Regular Season'!I6+Postseason!I6 -> 2 | ... R6: ='Regular Season'!R6+Postseason!R6 -> 49 | S6: =if(D6=0,"-", F6/D6) -> 0.38961039 | T6: =if(C6=0, "-", (F6+M6+O6)/(D6+M6+O6+P6)) -> 0.51515152 | U6: =iferror(if(C6=0, "-", R6/D6), 0) -> 0.63636364 | V6: =if(T6="-", "-", T6+U6) -> 1.1515152 | W6: =if(C6=0,"-", ((F6+M6)*R6)/(D6+M6)) -> 25.010417 | X6: =if(C6=0, "-", M6/C6) -> 0.19191919 | Y6: =if(C6=0, "-", N6/C6) -> 0.2020202 | Z6: =ifs(Y6="-", "-", Y6=0, "0", Y6<>0, M6/N6) -> 0.95 | AA6: =IF(K6=0, "-", D6/K6) -> 77 | AB6: =if(C6=0, "-", ((0.69*M6)+(0.72*O6)+(0.88*H6)+(1.24*I6)+(1.57*J6)+(2*K6))/(D6+M6+O6+P6)) -> 0.4810101 | AC6: =if(D6=0, "-",'Regular Season'!AC6+Postseason!AC6) -> 23 | AD6: ='Regular Season'!AD6+Postseason!AD6 -> 2 | AE6: =if(L6=0, "-", L6/(L6+AD6)) -> 0.90909091 | AF6: ='Regular Season'!AF6+Postseason!AF6 -> 3 | AG6: =iferror((F6-K6)/(D6-K6-N6+P6), "-") -> 0.50877193 | AH6: =iferror((R6-F6)/D6, "-") -> 0.24675325 | AI6: =iferror(2*(K6*L6)/(K6+L6), "-") -> 1.9047619
A7: Charlie Valencic (Sr) | B7: ='Regular Season'!B7+Postseason!B7 -> 27 | C7: ='Regular Season'!C7+Postseason!C7 -> 76 | D7: ='Regular Season'!D7+Postseason!D7 -> 60 | E7: ='Regular Season'!E7+Postseason!E7 -> 19 | F7: ='Regular Season'!F7+Postseason!F7 -> 17 | G7: ='Regular Season'!G7+Postseason!G7 -> 17 | H7: ='Regular Season'!H7+Postseason!H7 -> 12 | I7: ='Regular Season'!I7+Postseason!I7 -> 3 | ... R7: ='Regular Season'!R7+Postseason!R7 -> 24 | S7: =if(D7=0,"-", F7/D7) -> 0.28333333 | T7: =if(C7=0, "-", (F7+M7+O7)/(D7+M7+O7+P7)) -> 0.39189189 | U7: =iferror(if(C7=0, "-", R7/D7), 0) -> 0.4 | V7: =if(T7="-", "-", T7+U7) -> 0.79189189 | W7: =if(C7=0,"-", ((F7+M7)*R7)/(D7+M7)) -> 9.6666667 | X7: =if(C7=0, "-", M7/C7) -> 0.15789474 | Y7: =if(C7=0, "-", N7/C7) -> 0.11842105 | Z7: =ifs(Y7="-", "-", Y7=0, "0", Y7<>0, M7/N7) -> 1.3333333 | AA7: =IF(K7=0, "-", D7/K7) -> - | AB7: =if(C7=0, "-", ((0.69*M7)+(0.72*O7)+(0.88*H7)+(1.24*I7)+(1.57*J7)+(2*K7))/(D7+M7+O7+P7)) -> 0.3472973 | AC7: =if(D7=0, "-",'Regular Season'!AC7+Postseason!AC7) -> 18 | AD7: ='Regular Season'!AD7+Postseason!AD7 -> 3 | AE7: =if(L7=0, "-", L7/(L7+AD7)) -> 0.66666667 | AF7: ='Regular Season'!AF7+Postseason!AF7 -> 4 | AG7: =iferror((F7-K7)/(D7-K7-N7+P7), "-") -> 0.32075472 | AH7: =iferror((R7-F7)/D7, "-") -> 0.11666667 | AI7: =iferror(2*(K7*L7)/(K7+L7), "-") -> 0
A8: Conner Cuozzo (Jr) | B8: ='Regular Season'!B8+Postseason!B8 -> 28 | C8: ='Regular Season'!C8+Postseason!C8 -> 97 | D8: ='Regular Season'!D8+Postseason!D8 -> 82 | E8: ='Regular Season'!E8+Postseason!E8 -> 27 | F8: ='Regular Season'!F8+Postseason!F8 -> 32 | G8: ='Regular Season'!G8+Postseason!G8 -> 32 | H8: ='Regular Season'!H8+Postseason!H8 -> 17 | I8: ='Regular Season'!I8+Postseason!I8 -> 6 | ... R8: ='Regular Season'!R8+Postseason!R8 -> 64 | S8: =if(D8=0,"-", F8/D8) -> 0.3902439 | T8: =if(C8=0, "-", (F8+M8+O8)/(D8+M8+O8+P8)) -> 0.48453608 | U8: =iferror(if(C8=0, "-", R8/D8), 0) -> 0.7804878 | V8: =if(T8="-", "-", T8+U8) -> 1.2650239 | W8: =if(C8=0,"-", ((F8+M8)*R8)/(D8+M8)) -> 30.666667 | X8: =if(C8=0, "-", M8/C8) -> 0.1443299 | Y8: =if(C8=0, "-", N8/C8) -> 0.22680412 | Z8: =ifs(Y8="-", "-", Y8=0, "0", Y8<>0, M8/N8) -> 0.63636364 | AA8: =IF(K8=0, "-", D8/K8) -> 10.25 | AB8: =if(C8=0, "-", ((0.69*M8)+(0.72*O8)+(0.88*H8)+(1.24*I8)+(1.57*J8)+(2*K8))/(D8+M8+O8+P8)) -> 0.51907216 | AC8: =if(D8=0, "-",'Regular Season'!AC8+Postseason!AC8) -> 14 | AD8: ='Regular Season'!AD8+Postseason!AD8 -> 4 | AE8: =if(L8=0, "-", L8/(L8+AD8)) -> 0.71428571 | AF8: ='Regular Season'!AF8+Postseason!AF8 -> 1 | AG8: =iferror((F8-K8)/(D8-K8-N8+P8), "-") -> 0.46153846 | AH8: =iferror((R8-F8)/D8, "-") -> 0.3902439 | AI8: =iferror(2*(K8*L8)/(K8+L8), "-") -> 8.8888889
A9: Cooper Ridley (Sr) | B9: ='Regular Season'!B9+Postseason!B9 -> 24 | C9: ='Regular Season'!C9+Postseason!C9 -> 77 | D9: ='Regular Season'!D9+Postseason!D9 -> 65 | E9: ='Regular Season'!E9+Postseason!E9 -> 19 | F9: ='Regular Season'!F9+Postseason!F9 -> 21 | G9: ='Regular Season'!G9+Postseason!G9 -> 20 | H9: ='Regular Season'!H9+Postseason!H9 -> 11 | I9: ='Regular Season'!I9+Postseason!I9 -> 3 | ... R9: ='Regular Season'!R9+Postseason!R9 -> 41 | S9: =if(D9=0,"-", F9/D9) -> 0.32307692 | T9: =if(C9=0, "-", (F9+M9+O9)/(D9+M9+O9+P9)) -> 0.42857143 | U9: =iferror(if(C9=0, "-", R9/D9), 0) -> 0.63076923 | V9: =if(T9="-", "-", T9+U9) -> 1.0593407 | W9: =if(C9=0,"-", ((F9+M9)*R9)/(D9+M9)) -> 17.263158 | X9: =if(C9=0, "-", M9/C9) -> 0.14285714 | Y9: =if(C9=0, "-", N9/C9) -> 0.28571429 | Z9: =ifs(Y9="-", "-", Y9=0, "0", Y9<>0, M9/N9) -> 0.5 | AA9: =IF(K9=0, "-", D9/K9) -> 21.666667 | AB9: =if(C9=0, "-", ((0.69*M9)+(0.72*O9)+(0.88*H9)+(1.24*I9)+(1.57*J9)+(2*K9))/(D9+M9+O9+P9)) -> 0.44142857 | AC9: =if(D9=0, "-",'Regular Season'!AC9+Postseason!AC9) -> 11 | AD9: ='Regular Season'!AD9+Postseason!AD9 -> 1 | AE9: =if(L9=0, "-", L9/(L9+AD9)) -> 0.92857143 | AF9: ='Regular Season'!AF9+Postseason!AF9 -> 0 | AG9: =iferror((F9-K9)/(D9-K9-N9+P9), "-") -> 0.45 | AH9: =iferror((R9-F9)/D9, "-") -> 0.30769231 | AI9: =iferror(2*(K9*L9)/(K9+L9), "-") -> 4.875
A10: Donovan Glosser (So) | B10: ='Regular Season'!B10+Postseason!B10 -> 22 | C10: ='Regular Season'!C10+Postseason!C10 -> 60 | D10: ='Regular Season'!D10+Postseason!D10 -> 42 | E10: ='Regular Season'!E10+Postseason!E10 -> 11 | F10: ='Regular Season'!F10+Postseason!F10 -> 7 | G10: ='Regular Season'!G10+Postseason!G10 -> 6 | H10: ='Regular Season'!H10+Postseason!H10 -> 6 | I10: ='Regular Season'!I10+Postseason!I10 -> 1 | ... R10: ='Regular Season'!R10+Postseason!R10 -> 8 | S10: =if(D10=0,"-", F10/D10) -> 0.16666667 | T10: =if(C10=0, "-", (F10+M10+O10)/(D10+M10+O10+P10)) -> 0.36842105 | U10: =iferror(if(C10=0, "-", R10/D10), 0) -> 0.19047619 | V10: =if(T10="-", "-", T10+U10) -> 0.55889724 | W10: =if(C10=0,"-", ((F10+M10)*R10)/(D10+M10)) -> 2.8148148 | X10: =if(C10=0, "-", M10/C10) -> 0.2 | Y10: =if(C10=0, "-", N10/C10) -> 0.16666667 | Z10: =ifs(Y10="-", "-", Y10=0, "0", Y10<>0, M10/N10) -> 1.2 | AA10: =IF(K10=0, "-", D10/K10) -> - | AB10: =if(C10=0, "-", ((0.69*M10)+(0.72*O10)+(0.88*H10)+(1.24*I10)+(1.57*J10)+(2*K10))/(D10+M10+O10+P10)) -> 0.28491228 | AC10: =if(D10=0, "-",'Regular Season'!AC10+Postseason!AC10) -> 8 | AD10: ='Regular Season'!AD10+Postseason!AD10 -> 0 | AE10: =if(L10=0, "-", L10/(L10+AD10)) -> 1 | AF10: ='Regular Season'!AF10+Postseason!AF10 -> 2 | AG10: =iferror((F10-K10)/(D10-K10-N10+P10), "-") -> 0.21212121 | AH10: =iferror((R10-F10)/D10, "-") -> 0.023809524 | AI10: =iferror(2*(K10*L10)/(K10+L10), "-") -> 0
A11: Griffin Booth (Sr) | B11: ='Regular Season'!B11+Postseason!B11 -> 10 | C11: ='Regular Season'!C11+Postseason!C11 -> 25 | D11: ='Regular Season'!D11+Postseason!D11 -> 18 | E11: ='Regular Season'!E11+Postseason!E11 -> 6 | F11: ='Regular Season'!F11+Postseason!F11 -> 3 | G11: ='Regular Season'!G11+Postseason!G11 -> 3 | H11: ='Regular Season'!H11+Postseason!H11 -> 2 | I11: ='Regular Season'!I11+Postseason!I11 -> 1 | ... R11: ='Regular Season'!R11+Postseason!R11 -> 4 | S11: =if(D11=0,"-", F11/D11) -> 0.16666667 | T11: =if(C11=0, "-", (F11+M11+O11)/(D11+M11+O11+P11)) -> 0.34782609 | U11: =iferror(if(C11=0, "-", R11/D11), 0) -> 0.22222222 | V11: =if(T11="-", "-", T11+U11) -> 0.57004831 | W11: =if(C11=0,"-", ((F11+M11)*R11)/(D11+M11)) -> 1.3913043 | X11: =if(C11=0, "-", M11/C11) -> 0.2 | Y11: =if(C11=0, "-", N11/C11) -> 0.16 | Z11: =ifs(Y11="-", "-", Y11=0, "0", Y11<>0, M11/N11) -> 1.25 | AA11: =IF(K11=0, "-", D11/K11) -> - | AB11: =if(C11=0, "-", ((0.69*M11)+(0.72*O11)+(0.88*H11)+(1.24*I11)+(1.57*J11)+(2*K11))/(D11+M11+O11+P11)) -> 0.28043478 | AC11: =if(D11=0, "-",'Regular Season'!AC11+Postseason!AC11) -> 2 | AD11: ='Regular Season'!AD11+Postseason!AD11 -> 0 | AE11: =if(L11=0, "-", L11/(L11+AD11)) -> - | AF11: ='Regular Season'!AF11+Postseason!AF11 -> 1 | AG11: =iferror((F11-K11)/(D11-K11-N11+P11), "-") -> 0.21428571 | AH11: =iferror((R11-F11)/D11, "-") -> 0.055555556 | AI11: =iferror(2*(K11*L11)/(K11+L11), "-") -> -
A12: Jackson Porta (Sr) | B12: ='Regular Season'!B12+Postseason!B12 -> 27 | C12: ='Regular Season'!C12+Postseason!C12 -> 79 | D12: ='Regular Season'!D12+Postseason!D12 -> 66 | E12: ='Regular Season'!E12+Postseason!E12 -> 14 | F12: ='Regular Season'!F12+Postseason!F12 -> 19 | G12: ='Regular Season'!G12+Postseason!G12 -> 19 | H12: ='Regular Season'!H12+Postseason!H12 -> 13 | I12: ='Regular Season'!I12+Postseason!I12 -> 5 | ... R12: ='Regular Season'!R12+Postseason!R12 -> 26 | S12: =if(D12=0,"-", F12/D12) -> 0.28787879 | T12: =if(C12=0, "-", (F12+M12+O12)/(D12+M12+O12+P12)) -> 0.36363636 | U12: =iferror(if(C12=0, "-", R12/D12), 0) -> 0.39393939 | V12: =if(T12="-", "-", T12+U12) -> 0.75757576 | W12: =if(C12=0,"-", ((F12+M12)*R12)/(D12+M12)) -> 9.7066667 | X12: =if(C12=0, "-", M12/C12) -> 0.11392405 | Y12: =if(C12=0, "-", N12/C12) -> 0.15189873 | Z12: =ifs(Y12="-", "-", Y12=0, "0", Y12<>0, M12/N12) -> 0.75 | AA12: =IF(K12=0, "-", D12/K12) -> - | AB12: =if(C12=0, "-", ((0.69*M12)+(0.72*O12)+(0.88*H12)+(1.24*I12)+(1.57*J12)+(2*K12))/(D12+M12+O12+P12)) -> 0.33012987 | AC12: =if(D12=0, "-",'Regular Season'!AC12+Postseason!AC12) -> 16 | AD12: ='Regular Season'!AD12+Postseason!AD12 -> 1 | AE12: =if(L12=0, "-", L12/(L12+AD12)) -> 0.92307692 | AF12: ='Regular Season'!AF12+Postseason!AF12 -> 0 | AG12: =iferror((F12-K12)/(D12-K12-N12+P12), "-") -> 0.33928571 | AH12: =iferror((R12-F12)/D12, "-") -> 0.10606061 | AI12: =iferror(2*(K12*L12)/(K12+L12), "-") -> 0
A13: Jake Bell (Sr) | B13: ='Regular Season'!B13+Postseason!B13 -> 15 | C13: ='Regular Season'!C13+Postseason!C13 -> 44 | D13: ='Regular Season'!D13+Postseason!D13 -> 30 | E13: ='Regular Season'!E13+Postseason!E13 -> 12 | F13: ='Regular Season'!F13+Postseason!F13 -> 11 | G13: ='Regular Season'!G13+Postseason!G13 -> 7 | H13: ='Regular Season'!H13+Postseason!H13 -> 8 | I13: ='Regular Season'!I13+Postseason!I13 -> 2 | ... R13: ='Regular Season'!R13+Postseason!R13 -> 15 | S13: =if(D13=0,"-", F13/D13) -> 0.36666667 | T13: =if(C13=0, "-", (F13+M13+O13)/(D13+M13+O13+P13)) -> 0.525 | U13: =iferror(if(C13=0, "-", R13/D13), 0) -> 0.5 | V13: =if(T13="-", "-", T13+U13) -> 1.025 | W13: =if(C13=0,"-", ((F13+M13)*R13)/(D13+M13)) -> 7.6923077 | X13: =if(C13=0, "-", M13/C13) -> 0.20454545 | Y13: =if(C13=0, "-", N13/C13) -> 0.20454545 | Z13: =ifs(Y13="-", "-", Y13=0, "0", Y13<>0, M13/N13) -> 1 | AA13: =IF(K13=0, "-", D13/K13) -> - | AB13: =if(C13=0, "-", ((0.69*M13)+(0.72*O13)+(0.88*H13)+(1.24*I13)+(1.57*J13)+(2*K13))/(D13+M13+O13+P13)) -> 0.4505 | AC13: =if(D13=0, "-",'Regular Season'!AC13+Postseason!AC13) -> 9 | AD13: ='Regular Season'!AD13+Postseason!AD13 -> 0 | AE13: =if(L13=0, "-", L13/(L13+AD13)) -> 1 | AF13: ='Regular Season'!AF13+Postseason!AF13 -> 1 | AG13: =iferror((F13-K13)/(D13-K13-N13+P13), "-") -> 0.52380952 | AH13: =iferror((R13-F13)/D13, "-") -> 0.13333333 | AI13: =iferror(2*(K13*L13)/(K13+L13), "-") -> 0
A14: Jovan Love (Sr) | B14: ='Regular Season'!B14+Postseason!B14 -> 26 | C14: ='Regular Season'!C14+Postseason!C14 -> 86 | D14: ='Regular Season'!D14+Postseason!D14 -> 66 | E14: ='Regular Season'!E14+Postseason!E14 -> 28 | F14: ='Regular Season'!F14+Postseason!F14 -> 24 | G14: ='Regular Season'!G14+Postseason!G14 -> 24 | H14: ='Regular Season'!H14+Postseason!H14 -> 15 | I14: ='Regular Season'!I14+Postseason!I14 -> 4 | ... R14: ='Regular Season'!R14+Postseason!R14 -> 42 | S14: =if(D14=0,"-", F14/D14) -> 0.36363636 | T14: =if(C14=0, "-", (F14+M14+O14)/(D14+M14+O14+P14)) -> 0.47674419 | U14: =iferror(if(C14=0, "-", R14/D14), 0) -> 0.63636364 | V14: =if(T14="-", "-", T14+U14) -> 1.1131078 | W14: =if(C14=0,"-", ((F14+M14)*R14)/(D14+M14)) -> 19.95 | X14: =if(C14=0, "-", M14/C14) -> 0.1627907 | Y14: =if(C14=0, "-", N14/C14) -> 0.20930233 | Z14: =ifs(Y14="-", "-", Y14=0, "0", Y14<>0, M14/N14) -> 0.77777778 | AA14: =IF(K14=0, "-", D14/K14) -> 16.5 | AB14: =if(C14=0, "-", ((0.69*M14)+(0.72*O14)+(0.88*H14)+(1.24*I14)+(1.57*J14)+(2*K14))/(D14+M14+O14+P14)) -> 0.45988372 | AC14: =if(D14=0, "-",'Regular Season'!AC14+Postseason!AC14) -> 20 | AD14: ='Regular Season'!AD14+Postseason!AD14 -> 0 | AE14: =if(L14=0, "-", L14/(L14+AD14)) -> 1 | AF14: ='Regular Season'!AF14+Postseason!AF14 -> 1 | AG14: =iferror((F14-K14)/(D14-K14-N14+P14), "-") -> 0.42553191 | AH14: =iferror((R14-F14)/D14, "-") -> 0.27272727 | AI14: =iferror(2*(K14*L14)/(K14+L14), "-") -> 6.4
A15: Kayde Ridley (Jr) | B15: ='Regular Season'!B15+Postseason!B15 -> 2 | C15: ='Regular Season'!C15+Postseason!C15 -> 2 | D15: ='Regular Season'!D15+Postseason!D15 -> 1 | E15: ='Regular Season'!E15+Postseason!E15 -> 0 | F15: ='Regular Season'!F15+Postseason!F15 -> 1 | G15: ='Regular Season'!G15+Postseason!G15 -> 1 | H15: ='Regular Season'!H15+Postseason!H15 -> 1 | I15: ='Regular Season'!I15+Postseason!I15 -> 0 | ... R15: ='Regular Season'!R15+Postseason!R15 -> 1 | S15: =if(D15=0,"-", F15/D15) -> 1 | T15: =if(C15=0, "-", (F15+M15+O15)/(D15+M15+O15+P15)) -> 1 | U15: =iferror(if(C15=0, "-", R15/D15), 0) -> 1 | V15: =if(T15="-", "-", T15+U15) -> 2 | W15: =if(C15=0,"-", ((F15+M15)*R15)/(D15+M15)) -> 1 | X15: =if(C15=0, "-", M15/C15) -> 0.5 | Y15: =if(C15=0, "-", N15/C15) -> 0 | Z15: =ifs(Y15="-", "-", Y15=0, "0", Y15<>0, M15/N15) -> 0 | AA15: =IF(K15=0, "-", D15/K15) -> - | AB15: =if(C15=0, "-", ((0.69*M15)+(0.72*O15)+(0.88*H15)+(1.24*I15)+(1.57*J15)+(2*K15))/(D15+M15+O15+P15)) -> 0.785 | AC15: =if(D15=0, "-",'Regular Season'!AC15+Postseason!AC15) -> 0 | AD15: ='Regular Season'!AD15+Postseason!AD15 -> 0 | AE15: =if(L15=0, "-", L15/(L15+AD15)) -> - | AF15: ='Regular Season'!AF15+Postseason!AF15 -> 0 | AG15: =iferror((F15-K15)/(D15-K15-N15+P15), "-") -> 1 | AH15: =iferror((R15-F15)/D15, "-") -> 0 | AI15: =iferror(2*(K15*L15)/(K15+L15), "-") -> -
... A21: Will Schirmer (Sr) | B21: ='Regular Season'!B21+Postseason!B21 -> 17 | C21: ='Regular Season'!C21+Postseason!C21 -> 40 | D21: ='Regular Season'!D21+Postseason!D21 -> 31 | E21: ='Regular Season'!E21+Postseason!E21 -> 15 | F21: ='Regular Season'!F21+Postseason!F21 -> 15 | G21: ='Regular Season'!G21+Postseason!G21 -> 12 | H21: ='Regular Season'!H21+Postseason!H21 -> 13 | I21: ='Regular Season'!I21+Postseason!I21 -> 0 | ... R21: ='Regular Season'!R21+Postseason!R21 -> 20 | S21: =if(D21=0,"-", F21/D21) -> 0.48387097 | T21: =if(C21=0, "-", (F21+M21+O21)/(D21+M21+O21+P21)) -> 0.52631579 | U21: =iferror(if(C21=0, "-", R21/D21), 0) -> 0.64516129 | V21: =if(T21="-", "-", T21+U21) -> 1.1714771 | W21: =if(C21=0,"-", ((F21+M21)*R21)/(D21+M21)) -> 11.111111 | X21: =if(C21=0, "-", M21/C21) -> 0.125 | Y21: =if(C21=0, "-", N21/C21) -> 0.075 | Z21: =ifs(Y21="-", "-", Y21=0, "0", Y21<>0, M21/N21) -> 1.6666667 | AA21: =IF(K21=0, "-", D21/K21) -> 31 | AB21: =if(C21=0, "-", ((0.69*M21)+(0.72*O21)+(0.88*H21)+(1.24*I21)+(1.57*J21)+(2*K21))/(D21+M21+O21+P21)) -> 0.48578947 | AC21: =if(D21=0, "-",'Regular Season'!AC21+Postseason!AC21) -> 3 | AD21: ='Regular Season'!AD21+Postseason!AD21 -> 2 | AE21: =if(L21=0, "-", L21/(L21+AD21)) -> 0.66666667 | AF21: ='Regular Season'!AF21+Postseason!AF21 -> 2 | AG21: =iferror((F21-K21)/(D21-K21-N21+P21), "-") -> 0.48275862 | AH21: =iferror((R21-F21)/D21, "-") -> 0.16129032 | AI21: =iferror(2*(K21*L21)/(K21+L21), "-") -> 1.6
A22: Totals | C22: =sum(C3:C21) -> 957 | D22: =sum(D3:D21) -> 751 | E22: =sum(E3:E21) -> 265 | F22: =sum(F3:F21) -> 263 | G22: =sum(G3:G21) -> 231 | H22: =F22-(I22+J22+K22) -> 180 | I22: =sum(I3:I21) -> 41 | J22: =sum(J3:J21) -> 21 | K22: =sum(K3:K21) -> 21 | L22: =sum(L3:L21) -> 129 | M22: =sum(M3:M21) -> 155 | N22: =sum(N3:N21) -> 170 | O22: =sum(O3:O21) -> 19 | P22: =sum(P3:P21) -> 16 | Q22: =sum(Q3:Q21) -> 16 | R22: =(H22+(2*I22)+(3*J22)+(4*K22)) -> 409 | S22: =iferror(F22/D22, 0) -> 0.35019973 | T22: =iferror((F22+M22+O22)/(D22+M22+O22+P22), 0) -> 0.46439957 | U22: =iferror(R22/D22, 0) -> 0.54460719 | V22: =T22+U22 -> 1.0090068 | W22: =iferror(((F22+M22)*R22)/(D22+M22), 0) -> 188.69978 | X22: =iferror(M22/C22, 0) -> 0.16196447 | Y22: =iferror(N22/C22, 0) -> 0.17763845 | Z22: =ifs(Y22="-", "-", Y22=0, "0", Y22<>0, M22/N22) -> 0.91176471 | AA22: =IF(K22=0, "-", D22/K22) -> 35.761905 | AB22: =if(D22=0, "-", ((0.69*M22)+(0.72*O22)+(0.88*H22)+(1.24*I22)+(1.57*J22)+(2*K22))/(D22+M22+O22+P22)) -> 0.43022317 | AC22: ='Regular Season'!AC22+Postseason!AC22 -> 163 | AD22: =sum(AD3:AD21) -> 16 | AE22: =if(L22=0, "-", L22/(L22+AD22)) -> 0.88965517 | AF22: =sum(AF3:AF21) -> 19 | AG22: =iferror((F22-K22)/(D22-K22-N22+P22), "-") -> 0.42013889 | AH22: =iferror((R22-F22)/D22, "-") -> 0.19440746 | AI22: =iferror(2*(K22*L22)/(K22+L22), "-") -> 36.12
A24: Pitching Totals
A25: PLAYER | B25: G | C25: W-L% | D25: GS | E25: CG | F25: Full IP | G25: Partial IP | H25: IP | I25: H | J25: R | K25: ER | L25: BB | M25: K | N25: HR | O25: W | P25: L | Q25: SV | R25: SHO | S25: WHIP | T25: ERA | U25: H/7 | V25: BB/7 | W25: K/7 | X25: K/9 | Y25: HR/7 | Z25: BB/K | AA25: ERRORS
A26: Braylon Connell (Sr) | B26: ='Regular Season'!B26+Postseason!B26 -> 4 | C26: =IF((O26+P26)=0, "-", O26/(O26+P26)) -> 1 | D26: ='Regular Season'!D26+Postseason!D26 -> 1 | E26: ='Regular Season'!E26+Postseason!E26 -> 0 | F26: ='Regular Season'!F26+Postseason!F26 -> 7 | G26: ='Regular Season'!G26+Postseason!G26 -> 0.66666667 | H26: ='Regular Season'!H26+Postseason!H26 -> 7.2 | I26: ='Regular Season'!I26+Postseason!I26 -> 4 | J26: ='Regular Season'!J26+Postseason!J26 -> 4 | K26: ='Regular Season'!K26+Postseason!K26 -> 4 | ... R26: ='Regular Season'!R26+Postseason!R26 -> 0 | S26: =if(F26=0, "-", (L26+I26)/(F26+G26)) -> 1.3043478 | T26: =if(F26=0, "-", (K26/(F26+G26))*7) -> 3.6521739 | U26: =if(F26=0, "-", 7*(I26/(F26+G26))) -> 3.6521739 | V26: =if(F26=0, "-", 7*(L26/(F26+G26))) -> 5.4782609 | W26: =if(F26=0, "-", 7*(M26/(F26+G26))) -> 4.5652174 | X26: =if(F26=0, "-", 9*(M26/(F26+G26))) -> 5.8695652 | Y26: =if(F26=0, "-", 7*(N26/(F26+G26))) -> 0 | Z26: =if(M26=0,"-", L26/M26) -> 1.2 | AA26: ='Regular Season'!AA26+Postseason!AA26 -> 0
A27: Carter Christenson (Sr) | B27: ='Regular Season'!B27+Postseason!B27 -> 0 | C27: =IF((O27+P27)=0, "-", O27/(O27+P27)) -> - | D27: ='Regular Season'!D27+Postseason!D27 -> 0 | E27: ='Regular Season'!E27+Postseason!E27 -> 0 | F27: ='Regular Season'!F27+Postseason!F27 -> 0 | G27: ='Regular Season'!G27+Postseason!G27 -> 0 | H27: ='Regular Season'!H27+Postseason!H27 -> 0 | I27: ='Regular Season'!I27+Postseason!I27 -> 0 | J27: ='Regular Season'!J27+Postseason!J27 -> 0 | K27: ='Regular Season'!K27+Postseason!K27 -> 0 | ... R27: ='Regular Season'!R27+Postseason!R27 -> 0 | S27: =if(F27=0, "-", (L27+I27)/(F27+G27)) -> - | T27: =if(F27=0, "-", (K27/(F27+G27))*7) -> - | U27: =if(F27=0, "-", 7*(I27/(F27+G27))) -> - | V27: =if(F27=0, "-", 7*(L27/(F27+G27))) -> - | W27: =if(F27=0, "-", 7*(M27/(F27+G27))) -> - | X27: =if(F27=0, "-", 9*(M27/(F27+G27))) -> - | Y27: =if(F27=0, "-", 7*(N27/(F27+G27))) -> - | Z27: =if(M27=0,"-", L27/M27) -> - | AA27: ='Regular Season'!AA27+Postseason!AA27 -> 0
A28: Connor Fuhrer (Sr) | B28: ='Regular Season'!B28+Postseason!B28 -> 10 | C28: =IF((O28+P28)=0, "-", O28/(O28+P28)) -> 1 | D28: ='Regular Season'!D28+Postseason!D28 -> 9 | E28: ='Regular Season'!E28+Postseason!E28 -> 2 | F28: ='Regular Season'!F28+Postseason!F28 -> 53 | G28: ='Regular Season'!G28+Postseason!G28 -> 0 | H28: ='Regular Season'!H28+Postseason!H28 -> 53 | I28: ='Regular Season'!I28+Postseason!I28 -> 40 | J28: ='Regular Season'!J28+Postseason!J28 -> 22 | K28: ='Regular Season'!K28+Postseason!K28 -> 17 | ... R28: ='Regular Season'!R28+Postseason!R28 -> 2 | S28: =if(F28=0, "-", (L28+I28)/(F28+G28)) -> 1.1886792 | T28: =if(F28=0, "-", (K28/(F28+G28))*7) -> 2.245283 | U28: =if(F28=0, "-", 7*(I28/(F28+G28))) -> 5.2830189 | V28: =if(F28=0, "-", 7*(L28/(F28+G28))) -> 3.0377358 | W28: =if(F28=0, "-", 7*(M28/(F28+G28))) -> 5.6792453 | X28: =if(F28=0, "-", 9*(M28/(F28+G28))) -> 7.3018868 | Y28: =if(F28=0, "-", 7*(N28/(F28+G28))) -> 0.13207547 | Z28: =if(M28=0,"-", L28/M28) -> 0.53488372 | AA28: ='Regular Season'!AA28+Postseason!AA28 -> 1
A29: Connor Scoggins (Sr) | B29: ='Regular Season'!B29+Postseason!B29 -> 5 | C29: =IF((O29+P29)=0, "-", O29/(O29+P29)) -> 1 | D29: ='Regular Season'!D29+Postseason!D29 -> 0 | E29: ='Regular Season'!E29+Postseason!E29 -> 0 | F29: ='Regular Season'!F29+Postseason!F29 -> 9 | G29: ='Regular Season'!G29+Postseason!G29 -> 0.33333333 | H29: ='Regular Season'!H29+Postseason!H29 -> 9.1 | I29: ='Regular Season'!I29+Postseason!I29 -> 7 | J29: ='Regular Season'!J29+Postseason!J29 -> 4 | K29: ='Regular Season'!K29+Postseason!K29 -> 2 | ... R29: ='Regular Season'!R29+Postseason!R29 -> 0 | S29: =if(F29=0, "-", (L29+I29)/(F29+G29)) -> 1.7142857 | T29: =if(F29=0, "-", (K29/(F29+G29))*7) -> 1.5 | U29: =if(F29=0, "-", 7*(I29/(F29+G29))) -> 5.25 | V29: =if(F29=0, "-", 7*(L29/(F29+G29))) -> 6.75 | W29: =if(F29=0, "-", 7*(M29/(F29+G29))) -> 3 | X29: =if(F29=0, "-", 9*(M29/(F29+G29))) -> 3.8571429 | Y29: =if(F29=0, "-", 7*(N29/(F29+G29))) -> 0 | Z29: =if(M29=0,"-", L29/M29) -> 2.25 | AA29: ='Regular Season'!AA29+Postseason!AA29 -> 0
A30: Finn O'Keefe (Sr) | B30: ='Regular Season'!B30+Postseason!B30 -> 6 | C30: =IF((O30+P30)=0, "-", O30/(O30+P30)) -> 1 | D30: ='Regular Season'!D30+Postseason!D30 -> 0 | E30: ='Regular Season'!E30+Postseason!E30 -> 0 | F30: ='Regular Season'!F30+Postseason!F30 -> 9 | G30: ='Regular Season'!G30+Postseason!G30 -> 0.66666667 | H30: ='Regular Season'!H30+Postseason!H30 -> 9.2 | I30: ='Regular Season'!I30+Postseason!I30 -> 7 | J30: ='Regular Season'!J30+Postseason!J30 -> 7 | K30: ='Regular Season'!K30+Postseason!K30 -> 6 | ... R30: ='Regular Season'!R30+Postseason!R30 -> 0 | S30: =if(F30=0, "-", (L30+I30)/(F30+G30)) -> 1.7586207 | T30: =if(F30=0, "-", (K30/(F30+G30))*7) -> 4.3448276 | U30: =if(F30=0, "-", 7*(I30/(F30+G30))) -> 5.0689655 | V30: =if(F30=0, "-", 7*(L30/(F30+G30))) -> 7.2413793 | W30: =if(F30=0, "-", 7*(M30/(F30+G30))) -> 7.2413793 | X30: =if(F30=0, "-", 9*(M30/(F30+G30))) -> 9.3103448 | Y30: =if(F30=0, "-", 7*(N30/(F30+G30))) -> 1.4482759 | Z30: =if(M30=0,"-", L30/M30) -> 1 | AA30: ='Regular Season'!AA30+Postseason!AA30 -> 0
A31: Jake Gaerke (Jr) | B31: ='Regular Season'!B31+Postseason!B31 -> 7 | C31: =IF((O31+P31)=0, "-", O31/(O31+P31)) -> 1 | D31: ='Regular Season'!D31+Postseason!D31 -> 0 | E31: ='Regular Season'!E31+Postseason!E31 -> 0 | F31: ='Regular Season'!F31+Postseason!F31 -> 7 | G31: ='Regular Season'!G31+Postseason!G31 -> 0.66666667 | H31: ='Regular Season'!H31+Postseason!H31 -> 7.2 | I31: ='Regular Season'!I31+Postseason!I31 -> 8 | J31: ='Regular Season'!J31+Postseason!J31 -> 8 | K31: ='Regular Season'!K31+Postseason!K31 -> 8 | ... R31: ='Regular Season'!R31+Postseason!R31 -> 0 | S31: =if(F31=0, "-", (L31+I31)/(F31+G31)) -> 1.6956522 | T31: =if(F31=0, "-", (K31/(F31+G31))*7) -> 7.3043478 | U31: =if(F31=0, "-", 7*(I31/(F31+G31))) -> 7.3043478 | V31: =if(F31=0, "-", 7*(L31/(F31+G31))) -> 4.5652174 | W31: =if(F31=0, "-", 7*(M31/(F31+G31))) -> 6.3913043 | X31: =if(F31=0, "-", 9*(M31/(F31+G31))) -> 8.2173913 | Y31: =if(F31=0, "-", 7*(N31/(F31+G31))) -> 0 | Z31: =if(M31=0,"-", L31/M31) -> 0.71428571 | AA31: ='Regular Season'!AA31+Postseason!AA31 -> 0
A32: Joey Watts (Sr) | B32: ='Regular Season'!B32+Postseason!B32 -> 5 | C32: =IF((O32+P32)=0, "-", O32/(O32+P32)) -> 0 | D32: ='Regular Season'!D32+Postseason!D32 -> 0 | E32: ='Regular Season'!E32+Postseason!E32 -> 0 | F32: ='Regular Season'!F32+Postseason!F32 -> 4 | G32: ='Regular Season'!G32+Postseason!G32 -> 0.33333333 | H32: ='Regular Season'!H32+Postseason!H32 -> 4.1 | I32: ='Regular Season'!I32+Postseason!I32 -> 4 | J32: ='Regular Season'!J32+Postseason!J32 -> 11 | K32: ='Regular Season'!K32+Postseason!K32 -> 8 | ... R32: ='Regular Season'!R32+Postseason!R32 -> 0 | S32: =if(F32=0, "-", (L32+I32)/(F32+G32)) -> 3.2307692 | T32: =if(F32=0, "-", (K32/(F32+G32))*7) -> 12.923077 | U32: =if(F32=0, "-", 7*(I32/(F32+G32))) -> 6.4615385 | V32: =if(F32=0, "-", 7*(L32/(F32+G32))) -> 16.153846 | W32: =if(F32=0, "-", 7*(M32/(F32+G32))) -> 6.4615385 | X32: =if(F32=0, "-", 9*(M32/(F32+G32))) -> 8.3076923 | Y32: =if(F32=0, "-", 7*(N32/(F32+G32))) -> 0 | Z32: =if(M32=0,"-", L32/M32) -> 2.5 | AA32: ='Regular Season'!AA32+Postseason!AA32 -> 0
A33: Logan Rosenberger (Sr) | B33: ='Regular Season'!B33+Postseason!B33 -> 3 | C33: =IF((O33+P33)=0, "-", O33/(O33+P33)) -> - | D33: ='Regular Season'!D33+Postseason!D33 -> 1 | E33: ='Regular Season'!E33+Postseason!E33 -> 0 | F33: ='Regular Season'!F33+Postseason!F33 -> 4 | G33: ='Regular Season'!G33+Postseason!G33 -> 0.33333333 | H33: ='Regular Season'!H33+Postseason!H33 -> 4.1 | I33: ='Regular Season'!I33+Postseason!I33 -> 8 | J33: ='Regular Season'!J33+Postseason!J33 -> 7 | K33: ='Regular Season'!K33+Postseason!K33 -> 7 | ... R33: ='Regular Season'!R33+Postseason!R33 -> 0 | S33: =if(F33=0, "-", (L33+I33)/(F33+G33)) -> 3 | T33: =if(F33=0, "-", (K33/(F33+G33))*7) -> 11.307692 | U33: =if(F33=0, "-", 7*(I33/(F33+G33))) -> 12.923077 | V33: =if(F33=0, "-", 7*(L33/(F33+G33))) -> 8.0769231 | W33: =if(F33=0, "-", 7*(M33/(F33+G33))) -> 6.4615385 | X33: =if(F33=0, "-", 9*(M33/(F33+G33))) -> 8.3076923 | Y33: =if(F33=0, "-", 7*(N33/(F33+G33))) -> 0 | Z33: =if(M33=0,"-", L33/M33) -> 1.25 | AA33: ='Regular Season'!AA33+Postseason!AA33 -> 0
A34: Luke Pappano (Sr) | B34: ='Regular Season'!B34+Postseason!B34 -> 9 | C34: =IF((O34+P34)=0, "-", O34/(O34+P34)) -> 1 | D34: ='Regular Season'!D34+Postseason!D34 -> 6 | E34: ='Regular Season'!E34+Postseason!E34 -> 1 | F34: ='Regular Season'!F34+Postseason!F34 -> 31 | G34: ='Regular Season'!G34+Postseason!G34 -> 0.33333333 | H34: ='Regular Season'!H34+Postseason!H34 -> 31.1 | I34: ='Regular Season'!I34+Postseason!I34 -> 17 | J34: ='Regular Season'!J34+Postseason!J34 -> 14 | K34: ='Regular Season'!K34+Postseason!K34 -> 11 | ... R34: ='Regular Season'!R34+Postseason!R34 -> 1 | S34: =if(F34=0, "-", (L34+I34)/(F34+G34)) -> 1.0851064 | T34: =if(F34=0, "-", (K34/(F34+G34))*7) -> 2.4574468 | U34: =if(F34=0, "-", 7*(I34/(F34+G34))) -> 3.7978723 | V34: =if(F34=0, "-", 7*(L34/(F34+G34))) -> 3.7978723 | W34: =if(F34=0, "-", 7*(M34/(F34+G34))) -> 7.1489362 | X34: =if(F34=0, "-", 9*(M34/(F34+G34))) -> 9.1914894 | Y34: =if(F34=0, "-", 7*(N34/(F34+G34))) -> 0 | Z34: =if(M34=0,"-", L34/M34) -> 0.53125 | AA34: ='Regular Season'!AA34+Postseason!AA34 -> 1
A35: Matt Ponatoski (Jr) | B35: ='Regular Season'!B35+Postseason!B35 -> 4 | C35: =IF((O35+P35)=0, "-", O35/(O35+P35)) -> - | D35: ='Regular Season'!D35+Postseason!D35 -> 0 | E35: ='Regular Season'!E35+Postseason!E35 -> 0 | F35: ='Regular Season'!F35+Postseason!F35 -> 4 | G35: ='Regular Season'!G35+Postseason!G35 -> 0 | H35: ='Regular Season'!H35+Postseason!H35 -> 4 | I35: ='Regular Season'!I35+Postseason!I35 -> 1 | J35: ='Regular Season'!J35+Postseason!J35 -> 0 | K35: ='Regular Season'!K35+Postseason!K35 -> 0 | ... R35: ='Regular Season'!R35+Postseason!R35 -> 0 | S35: =if(F35=0, "-", (L35+I35)/(F35+G35)) -> 1 | T35: =if(F35=0, "-", (K35/(F35+G35))*7) -> 0 | U35: =if(F35=0, "-", 7*(I35/(F35+G35))) -> 1.75 | V35: =if(F35=0, "-", 7*(L35/(F35+G35))) -> 5.25 | W35: =if(F35=0, "-", 7*(M35/(F35+G35))) -> 3.5 | X35: =if(F35=0, "-", 9*(M35/(F35+G35))) -> 4.5 | Y35: =if(F35=0, "-", 7*(N35/(F35+G35))) -> 0 | Z35: =if(M35=0,"-", L35/M35) -> 1.5 | AA35: ='Regular Season'!AA35+Postseason!AA35 -> 0
A36: Nathan McDowell (So) | B36: ='Regular Season'!B36+Postseason!B36 -> 3 | C36: =IF((O36+P36)=0, "-", O36/(O36+P36)) -> 1 | D36: ='Regular Season'!D36+Postseason!D36 -> 3 | E36: ='Regular Season'!E36+Postseason!E36 -> 0 | F36: ='Regular Season'!F36+Postseason!F36 -> 13 | G36: ='Regular Season'!G36+Postseason!G36 -> 0.33333333 | H36: ='Regular Season'!H36+Postseason!H36 -> 13.1 | I36: ='Regular Season'!I36+Postseason!I36 -> 6 | J36: ='Regular Season'!J36+Postseason!J36 -> 2 | K36: ='Regular Season'!K36+Postseason!K36 -> 0 | ... R36: ='Regular Season'!R36+Postseason!R36 -> 1 | S36: =if(F36=0, "-", (L36+I36)/(F36+G36)) -> 0.6 | T36: =if(F36=0, "-", (K36/(F36+G36))*7) -> 0 | U36: =if(F36=0, "-", 7*(I36/(F36+G36))) -> 3.15 | V36: =if(F36=0, "-", 7*(L36/(F36+G36))) -> 1.05 | W36: =if(F36=0, "-", 7*(M36/(F36+G36))) -> 8.925 | X36: =if(F36=0, "-", 9*(M36/(F36+G36))) -> 11.475 | Y36: =if(F36=0, "-", 7*(N36/(F36+G36))) -> 0 | Z36: =if(M36=0,"-", L36/M36) -> 0.11764706 | AA36: ='Regular Season'!AA36+Postseason!AA36 -> 0
A37: Noah Goettke (So) | B37: ='Regular Season'!B37+Postseason!B37 -> 0 | C37: =IF((O37+P37)=0, "-", O37/(O37+P37)) -> - | D37: ='Regular Season'!D37+Postseason!D37 -> 0 | E37: ='Regular Season'!E37+Postseason!E37 -> 0 | F37: ='Regular Season'!F37+Postseason!F37 -> 0 | G37: ='Regular Season'!G37+Postseason!G37 -> 0 | H37: ='Regular Season'!H37+Postseason!H37 -> 0 | I37: ='Regular Season'!I37+Postseason!I37 -> 0 | J37: ='Regular Season'!J37+Postseason!J37 -> 0 | K37: ='Regular Season'!K37+Postseason!K37 -> 0 | ... R37: ='Regular Season'!R37+Postseason!R37 -> 0 | S37: =if(F37=0, "-", (L37+I37)/(F37+G37)) -> - | T37: =if(F37=0, "-", (K37/(F37+G37))*7) -> - | U37: =if(F37=0, "-", 7*(I37/(F37+G37))) -> - | V37: =if(F37=0, "-", 7*(L37/(F37+G37))) -> - | W37: =if(F37=0, "-", 7*(M37/(F37+G37))) -> - | X37: =if(F37=0, "-", 9*(M37/(F37+G37))) -> - | Y37: =if(F37=0, "-", 7*(N37/(F37+G37))) -> - | Z37: =if(M37=0,"-", L37/M37) -> - | AA37: ='Regular Season'!AA37+Postseason!AA37 -> 0
A38: Zion Theophilus (Sr) | B38: ='Regular Season'!B38+Postseason!B38 -> 9 | C38: =IF((O38+P38)=0, "-", O38/(O38+P38)) -> 0.71428571 | D38: ='Regular Season'!D38+Postseason!D38 -> 9 | E38: ='Regular Season'!E38+Postseason!E38 -> 2 | F38: ='Regular Season'!F38+Postseason!F38 -> 49 | G38: ='Regular Season'!G38+Postseason!G38 -> 0 | H38: ='Regular Season'!H38+Postseason!H38 -> 49 | I38: ='Regular Season'!I38+Postseason!I38 -> 29 | J38: ='Regular Season'!J38+Postseason!J38 -> 15 | K38: ='Regular Season'!K38+Postseason!K38 -> 14 | ... R38: ='Regular Season'!R38+Postseason!R38 -> 2 | S38: =if(F38=0, "-", (L38+I38)/(F38+G38)) -> 1.0204082 | T38: =if(F38=0, "-", (K38/(F38+G38))*7) -> 2 | U38: =if(F38=0, "-", 7*(I38/(F38+G38))) -> 4.1428571 | V38: =if(F38=0, "-", 7*(L38/(F38+G38))) -> 3 | W38: =if(F38=0, "-", 7*(M38/(F38+G38))) -> 11.857143 | X38: =if(F38=0, "-", 9*(M38/(F38+G38))) -> 15.244898 | Y38: =if(F38=0, "-", 7*(N38/(F38+G38))) -> 0 | Z38: =if(M38=0,"-", L38/M38) -> 0.25301205 | AA38: ='Regular Season'!AA38+Postseason!AA38 -> 0
A39: Totals | C39: =O39/(O39+P39) -> 0.86206897 | D39: =SUM(D26:D38) -> 29 | E39: =SUM(E26:E38) -> 5 | F39: =SUM(F26:F38) -> 190 | G39: =SUM(G26:G38) -> 3.6666667 | H39: =F39+ifs(G39=1/3, 0.1, G39=2/3, 0.2, G39=0, 0, G39=1, 1, G39=4/3, 1.1, G39=5/3, 1.2, G39=2, 2, G39=7/3, 2.1, G39=8/3, 2.2, G39=11/3, 3.2) -> 193.2 | I39: =SUM(I26:I38) -> 131 | J39: =SUM(J26:J38) -> 94 | K39: =SUM(K26:K38) -> 77 | L39: =SUM(L26:L38) -> 111 | M39: =SUM(M26:M38) -> 211 | N39: =SUM(N26:N38) -> 3 | O39: =SUM(O26:O38) -> 25 | P39: =SUM(P26:P38) -> 4 | ... R39: =SUM(R26:R38) -> 6 | S39: =iferror((L39+I39)/(F39+G39), 0) -> 1.2495697 | T39: =iferror((K39/(F39+G39))*7, 0) -> 2.7831325 | U39: =iferror(7*(I39/(F39+G39)), 0) -> 4.7349398 | V39: =iferror(7*(L39/(F39+G39)), 0) -> 4.0120482 | W39: =iferror(7*(M39/(F39+G39)), 0) -> 7.626506 | X39: =iferror(9*(M39/(F39+G39)), 0) -> 9.8055077 | Y39: =iferror(7*(N39/(F39+G39)), 0) -> 0.10843373 | Z39: =iferror(L39/M39, 0) -> 0.52606635 | AA39: =SUM(AA26:AA38) -> 2

Sheet Regular Season
A2: PLAYER | B2: G | C2: PA | D2: AB | E2: RUNS | F2: HITS | G2: RBI | H2: 1B | I2: 2B | J2: 3B | K2: HR | L2: SB | M2: BB | N2: K | O2: HBP | P2: SF | Q2: SH | R2: TB | S2: AVG | T2: OBP | U2: SLG | V2: OPS | W2: Runs Created | X2: BB% | Y2: K% | Z2: BB/K | AA2: AB/HR | AB2: wOBA | AC2: LOB | AD2: CS | AE2: SB% | AF2: ERRORS | AG2: BAbip | AH2: ISO | AI2: PwrSpd
A3: Adam Holstein (Jr) | B3: =COUNTIF('Game Stats'!A:A, A3) -> 4 | C3: =D3+M3+O3+P3+Q3 -> 5 | D3: =sumif('Game Stats'!$A:$A, $A3, 'Game Stats'!B:B) -> 3 | E3: =sumif('Game Stats'!$A:$A, $A3, 'Game Stats'!C:C) -> 3 | F3: =sumif('Game Stats'!$A:$A, $A3, 'Game Stats'!D:D) -> 0 | G3: =sumif('Game Stats'!$A:$A, $A3, 'Game Stats'!E:E) -> 0 | H3: =F3-(I3+J3+K3) -> 0 | I3: =sumif('Game Stats'!$A:$A, $A3, 'Game Stats'!G:G) -> 0 | J3: =sumif('Game Stats'!$A:$A, $A3, 'Game Stats'!H:H) -> 0 | K3: =sumif('Game Stats'!$A:$A, $A3, 'Game Stats'!I:I) -> 0 | L3: =sumif('Game Stats'!$A:$A, $A3, 'Game Stats'!Q:Q) -> 0 | M3: =sumif('Game Stats'!$A:$A, $A3, 'Game Stats'!J:J) -> 1 | N3: =sumif('Game Stats'!$A:$A, $A3, 'Game Stats'!K:K) -> 2 | O3: =sumif('Game Stats'!$A:$A, $A3, 'Game Stats'!N:N) -> 1 | P3: =sumif('Game Stats'!$A:$A, $A3, 'Game Stats'!L:L) -> 0 | Q3: =sumif('Game Stats'!$A:$A, $A3, 'Game Stats'!M:M) -> 0 | R3: =(H3+(2*I3)+(3*J3)+(4*K3)) -> 0 | S3: =iferror(if(C3=0,"-", F3/D3), 0) -> 0 | T3: =if(C3=0, "-", (F3+M3+O3)/(D3+M3+O3+P3)) -> 0.4 | U3: =iferror(if(C3=0, "-", R3/D3), 0) -> 0 | V3: =if(T3="-", "-", T3+U3) -> 0.4 | W3: =if(D3=0,"-", ((F3+M3)*R3)/(D3+M3)) -> 0 | X3: =if(C3=0, "-", M3/C3) -> 0.2 | Y3: =if(C3=0, "-", N3/C3) -> 0.4 | Z3: =ifs(Y3="-", "-", Y3=0, "0", Y3<>0, M3/N3) -> 0.5 | AA3: =IF(K3=0, "-", D3/K3) -> - | AB3: =if(C3=0, "-", ((0.69*M3)+(0.72*O3)+(0.88*H3)+(1.24*I3)+(1.57*J3)+(2*K3))/(D3+M3+O3+P3)) -> 0.282 | AC3: =if(D3=0, "-", sumif('Game Stats'!AD:AD, A3, 'Game Stats'!AC:AC)) -> 6 | AD3: 0 | AE3: =if(L3=0, "-", L3/(L3+AD3)) -> - | AF3: 0 | AG3: =iferror((F3-K3)/(D3-K3-N3+P3), "-") -> 0 | AH3: =iferror((R3-F3)/D3, "-") -> 0 | AI3: =iferror(2*(K3*L3)/(K3+L3), "-") -> -
A4: Adam Maybury (Jr) | B4: =COUNTIF('Game Stats'!A:A, A4) -> 9 | C4: =D4+M4+O4+P4+Q4 -> 16 | D4: =sumif('Game Stats'!$A:$A, $A4, 'Game Stats'!B:B) -> 12 | E4: =sumif('Game Stats'!$A:$A, $A4, 'Game Stats'!C:C) -> 4 | F4: =sumif('Game Stats'!$A:$A, $A4, 'Game Stats'!D:D) -> 2 | G4: =sumif('Game Stats'!$A:$A, $A4, 'Game Stats'!E:E) -> 1 | H4: =F4-(I4+J4+K4) -> 2 | I4: =sumif('Game Stats'!$A:$A, $A4, 'Game Stats'!G:G) -> 0 | J4: =sumif('Game Stats'!$A:$A, $A4, 'Game Stats'!H:H) -> 0 | K4: =sumif('Game Stats'!$A:$A, $A4, 'Game Stats'!I:I) -> 0 | L4: =sumif('Game Stats'!$A:$A, $A4, 'Game Stats'!Q:Q) -> 4 | M4: =sumif('Game Stats'!$A:$A, $A4, 'Game Stats'!J:J) -> 4 | N4: =sumif('Game Stats'!$A:$A, $A4, 'Game Stats'!K:K) -> 3 | O4: =sumif('Game Stats'!$A:$A, $A4, 'Game Stats'!N:N) -> 0 | P4: =sumif('Game Stats'!$A:$A, $A4, 'Game Stats'!L:L) -> 0 | Q4: =sumif('Game Stats'!$A:$A, $A4, 'Game Stats'!M:M) -> 0 | R4: =(H4+(2*I4)+(3*J4)+(4*K4)) -> 2 | S4: =iferror(if(C4=0,"-", F4/D4), 0) -> 0.16666667 | T4: =if(C4=0, "-", (F4+M4+O4)/(D4+M4+O4+P4)) -> 0.375 | U4: =iferror(if(C4=0, "-", R4/D4), 0) -> 0.16666667 | V4: =if(T4="-", "-", T4+U4) -> 0.54166667 | W4: =if(D4=0,"-", ((F4+M4)*R4)/(D4+M4)) -> 0.75 | X4: =if(C4=0, "-", M4/C4) -> 0.25 | Y4: =if(C4=0, "-", N4/C4) -> 0.1875 | Z4: =ifs(Y4="-", "-", Y4=0, "0", Y4<>0, M4/N4) -> 1.3333333 | AA4: =IF(K4=0, "-", D4/K4) -> - | AB4: =if(C4=0, "-", ((0.69*M4)+(0.72*O4)+(0.88*H4)+(1.24*I4)+(1.57*J4)+(2*K4))/(D4+M4+O4+P4)) -> 0.2825 | AC4: =if(D4=0, "-", sumif('Game Stats'!AD:AD, A4, 'Game Stats'!AC:AC)) -> 2 | AD4: 0 | AE4: =if(L4=0, "-", L4/(L4+AD4)) -> 1 | AF4: 0 | AG4: =iferror((F4-K4)/(D4-K4-N4+P4), "-") -> 0.22222222 | AH4: =iferror((R4-F4)/D4, "-") -> 0 | AI4: =iferror(2*(K4*L4)/(K4+L4), "-") -> 0
A5: Brody Foltz (Sr) | B5: =COUNTIF('Game Stats'!A:A, A5) -> 5 | C5: =D5+M5+O5+P5+Q5 -> 5 | D5: =sumif('Game Stats'!$A:$A, $A5, 'Game Stats'!B:B) -> 1 | E5: =sumif('Game Stats'!$A:$A, $A5, 'Game Stats'!C:C) -> 1 | F5: =sumif('Game Stats'!$A:$A, $A5, 'Game Stats'!D:D) -> 0 | G5: =sumif('Game Stats'!$A:$A, $A5, 'Game Stats'!E:E) -> 1 | H5: =F5-(I5+J5+K5) -> 0 | I5: =sumif('Game Stats'!$A:$A, $A5, 'Game Stats'!G:G) -> 0 | J5: =sumif('Game Stats'!$A:$A, $A5, 'Game Stats'!H:H) -> 0 | K5: =sumif('Game Stats'!$A:$A, $A5, 'Game Stats'!I:I) -> 0 | L5: =sumif('Game Stats'!$A:$A, $A5, 'Game Stats'!Q:Q) -> 0 | M5: =sumif('Game Stats'!$A:$A, $A5, 'Game Stats'!J:J) -> 3 | N5: =sumif('Game Stats'!$A:$A, $A5, 'Game Stats'!K:K) -> 1 | O5: =sumif('Game Stats'!$A:$A, $A5, 'Game Stats'!N:N) -> 1 | P5: =sumif('Game Stats'!$A:$A, $A5, 'Game Stats'!L:L) -> 0 | Q5: =sumif('Game Stats'!$A:$A, $A5, 'Game Stats'!M:M) -> 0 | R5: =(H5+(2*I5)+(3*J5)+(4*K5)) -> 0 | S5: =iferror(if(C5=0,"-", F5/D5), 0) -> 0 | T5: =if(C5=0, "-", (F5+M5+O5)/(D5+M5+O5+P5)) -> 0.8 | U5: =iferror(if(C5=0, "-", R5/D5), 0) -> 0 | V5: =if(T5="-", "-", T5+U5) -> 0.8 | W5: =if(D5=0,"-", ((F5+M5)*R5)/(D5+M5)) -> 0 | X5: =if(C5=0, "-", M5/C5) -> 0.6 | Y5: =if(C5=0, "-", N5/C5) -> 0.2 | Z5: =ifs(Y5="-", "-", Y5=0, "0", Y5<>0, M5/N5) -> 3 | AA5: =IF(K5=0, "-", D5/K5) -> - | AB5: =if(C5=0, "-", ((0.69*M5)+(0.72*O5)+(0.88*H5)+(1.24*I5)+(1.57*J5)+(2*K5))/(D5+M5+O5+P5)) -> 0.558 | AC5: =if(D5=0, "-", sumif('Game Stats'!AD:AD, A5, 'Game Stats'!AC:AC)) -> 0 | AD5: 0 | AE5: =if(L5=0, "-", L5/(L5+AD5)) -> - | AF5: 0 | AG5: =iferror((F5-K5)/(D5-K5-N5+P5), "-") -> - | AH5: =iferror((R5-F5)/D5, "-") -> 0 | AI5: =iferror(2*(K5*L5)/(K5+L5), "-") -> -
A6: Carter Christenson (Sr) | B6: =COUNTIF('Game Stats'!A:A, A6) -> 24 | C6: =D6+M6+O6+P6+Q6 -> 87 | D6: =sumif('Game Stats'!$A:$A, $A6, 'Game Stats'!B:B) -> 66 | E6: =sumif('Game Stats'!$A:$A, $A6, 'Game Stats'!C:C) -> 24 | F6: =sumif('Game Stats'!$A:$A, $A6, 'Game Stats'!D:D) -> 24 | G6: =sumif('Game Stats'!$A:$A, $A6, 'Game Stats'!E:E) -> 20 | H6: =F6-(I6+J6+K6) -> 17 | I6: =sumif('Game Stats'!$A:$A, $A6, 'Game Stats'!G:G) -> 0 | J6: =sumif('Game Stats'!$A:$A, $A6, 'Game Stats'!H:H) -> 6 | K6: =sumif('Game Stats'!$A:$A, $A6, 'Game Stats'!I:I) -> 1 | L6: =sumif('Game Stats'!$A:$A, $A6, 'Game Stats'!Q:Q) -> 17 | M6: =sumif('Game Stats'!$A:$A, $A6, 'Game Stats'!J:J) -> 18 | N6: =sumif('Game Stats'!$A:$A, $A6, 'Game Stats'!K:K) -> 18 | O6: =sumif('Game Stats'!$A:$A, $A6, 'Game Stats'!N:N) -> 2 | P6: =sumif('Game Stats'!$A:$A, $A6, 'Game Stats'!L:L) -> 1 | Q6: =sumif('Game Stats'!$A:$A, $A6, 'Game Stats'!M:M) -> 0 | R6: =(H6+(2*I6)+(3*J6)+(4*K6)) -> 39 | S6: =iferror(if(C6=0,"-", F6/D6), 0) -> 0.36363636 | T6: =if(C6=0, "-", (F6+M6+O6)/(D6+M6+O6+P6)) -> 0.50574713 | U6: =iferror(if(C6=0, "-", R6/D6), 0) -> 0.59090909 | V6: =if(T6="-", "-", T6+U6) -> 1.0966562 | W6: =if(D6=0,"-", ((F6+M6)*R6)/(D6+M6)) -> 19.5 | X6: =if(C6=0, "-", M6/C6) -> 0.20689655 | Y6: =if(C6=0, "-", N6/C6) -> 0.20689655 | Z6: =ifs(Y6="-", "-", Y6=0, "0", Y6<>0, M6/N6) -> 1 | AA6: =IF(K6=0, "-", D6/K6) -> 66 | AB6: =if(C6=0, "-", ((0.69*M6)+(0.72*O6)+(0.88*H6)+(1.24*I6)+(1.57*J6)+(2*K6))/(D6+M6+O6+P6)) -> 0.46252874 | AC6: =if(D6=0, "-", sumif('Game Stats'!AD:AD, A6, 'Game Stats'!AC:AC)) -> 23 | AD6: 2 | AE6: =if(L6=0, "-", L6/(L6+AD6)) -> 0.89473684 | AF6: 3 | AG6: =iferror((F6-K6)/(D6-K6-N6+P6), "-") -> 0.47916667 | AH6: =iferror((R6-F6)/D6, "-") -> 0.22727273 | AI6: =iferror(2*(K6*L6)/(K6+L6), "-") -> 1.8888889
A7: Charlie Valencic (Sr) | B7: =COUNTIF('Game Stats'!A:A, A7) -> 23 | C7: =D7+M7+O7+P7+Q7 -> 64 | D7: =sumif('Game Stats'!$A:$A, $A7, 'Game Stats'!B:B) -> 50 | E7: =sumif('Game Stats'!$A:$A, $A7, 'Game Stats'!C:C) -> 15 | F7: =sumif('Game Stats'!$A:$A, $A7, 'Game Stats'!D:D) -> 14 | G7: =sumif('Game Stats'!$A:$A, $A7, 'Game Stats'!E:E) -> 16 | H7: =F7-(I7+J7+K7) -> 9 | I7: =sumif('Game Stats'!$A:$A, $A7, 'Game Stats'!G:G) -> 3 | J7: =sumif('Game Stats'!$A:$A, $A7, 'Game Stats'!H:H) -> 2 | K7: =sumif('Game Stats'!$A:$A, $A7, 'Game Stats'!I:I) -> 0 | L7: =sumif('Game Stats'!$A:$A, $A7, 'Game Stats'!Q:Q) -> 5 | M7: =sumif('Game Stats'!$A:$A, $A7, 'Game Stats'!J:J) -> 11 | N7: =sumif('Game Stats'!$A:$A, $A7, 'Game Stats'!K:K) -> 8 | O7: =sumif('Game Stats'!$A:$A, $A7, 'Game Stats'!N:N) -> 0 | P7: =sumif('Game Stats'!$A:$A, $A7, 'Game Stats'!L:L) -> 1 | Q7: =sumif('Game Stats'!$A:$A, $A7, 'Game Stats'!M:M) -> 2 | R7: =(H7+(2*I7)+(3*J7)+(4*K7)) -> 21 | S7: =iferror(if(C7=0,"-", F7/D7), 0) -> 0.28 | T7: =if(C7=0, "-", (F7+M7+O7)/(D7+M7+O7+P7)) -> 0.40322581 | U7: =iferror(if(C7=0, "-", R7/D7), 0) -> 0.42 | V7: =if(T7="-", "-", T7+U7) -> 0.82322581 | W7: =if(D7=0,"-", ((F7+M7)*R7)/(D7+M7)) -> 8.6065574 | X7: =if(C7=0, "-", M7/C7) -> 0.171875 | Y7: =if(C7=0, "-", N7/C7) -> 0.125 | Z7: =ifs(Y7="-", "-", Y7=0, "0", Y7<>0, M7/N7) -> 1.375 | AA7: =IF(K7=0, "-", D7/K7) -> - | AB7: =if(C7=0, "-", ((0.69*M7)+(0.72*O7)+(0.88*H7)+(1.24*I7)+(1.57*J7)+(2*K7))/(D7+M7+O7+P7)) -> 0.36080645 | AC7: =if(D7=0, "-", sumif('Game Stats'!AD:AD, A7, 'Game Stats'!AC:AC)) -> 14 | AD7: 3 | AE7: =if(L7=0, "-", L7/(L7+AD7)) -> 0.625 | AF7: 4 | AG7: =iferror((F7-K7)/(D7-K7-N7+P7), "-") -> 0.3255814 | AH7: =iferror((R7-F7)/D7, "-") -> 0.14 | AI7: =iferror(2*(K7*L7)/(K7+L7), "-") -> 0
A8: Conner Cuozzo (Jr) | B8: =COUNTIF('Game Stats'!A:A, A8) -> 24 | C8: =D8+M8+O8+P8+Q8 -> 84 | D8: =sumif('Game Stats'!$A:$A, $A8, 'Game Stats'!B:B) -> 74 | E8: =sumif('Game Stats'!$A:$A, $A8, 'Game Stats'!C:C) -> 22 | F8: =sumif('Game Stats'!$A:$A, $A8, 'Game Stats'!D:D) -> 30 | G8: =sumif('Game Stats'!$A:$A, $A8, 'Game Stats'!E:E) -> 30 | H8: =F8-(I8+J8+K8) -> 16 | I8: =sumif('Game Stats'!$A:$A, $A8, 'Game Stats'!G:G) -> 6 | J8: =sumif('Game Stats'!$A:$A, $A8, 'Game Stats'!H:H) -> 1 | K8: =sumif('Game Stats'!$A:$A, $A8, 'Game Stats'!I:I) -> 7 | L8: =sumif('Game Stats'!$A:$A, $A8, 'Game Stats'!Q:Q) -> 9 | M8: =sumif('Game Stats'!$A:$A, $A8, 'Game Stats'!J:J) -> 10 | N8: =sumif('Game Stats'!$A:$A, $A8, 'Game Stats'!K:K) -> 19 | O8: =sumif('Game Stats'!$A:$A, $A8, 'Game Stats'!N:N) -> 0 | P8: =sumif('Game Stats'!$A:$A, $A8, 'Game Stats'!L:L) -> 0 | Q8: =sumif('Game Stats'!$A:$A, $A8, 'Game Stats'!M:M) -> 0 | R8: =(H8+(2*I8)+(3*J8)+(4*K8)) -> 59 | S8: =iferror(if(C8=0,"-", F8/D8), 0) -> 0.40540541 | T8: =if(C8=0, "-", (F8+M8+O8)/(D8+M8+O8+P8)) -> 0.47619048 | U8: =iferror(if(C8=0, "-", R8/D8), 0) -> 0.7972973 | V8: =if(T8="-", "-", T8+U8) -> 1.2734878 | W8: =if(D8=0,"-", ((F8+M8)*R8)/(D8+M8)) -> 28.095238 | X8: =if(C8=0, "-", M8/C8) -> 0.11904762 | Y8: =if(C8=0, "-", N8/C8) -> 0.22619048 | Z8: =ifs(Y8="-", "-", Y8=0, "0", Y8<>0, M8/N8) -> 0.52631579 | AA8: =IF(K8=0, "-", D8/K8) -> 10.571429 | AB8: =if(C8=0, "-", ((0.69*M8)+(0.72*O8)+(0.88*H8)+(1.24*I8)+(1.57*J8)+(2*K8))/(D8+M8+O8+P8)) -> 0.52369048 | AC8: =if(D8=0, "-", sumif('Game Stats'!AD:AD, A8, 'Game Stats'!AC:AC)) -> 14 | AD8: 3 | AE8: =if(L8=0, "-", L8/(L8+AD8)) -> 0.75 | AF8: 1 | AG8: =iferror((F8-K8)/(D8-K8-N8+P8), "-") -> 0.47916667 | AH8: =iferror((R8-F8)/D8, "-") -> 0.39189189 | AI8: =iferror(2*(K8*L8)/(K8+L8), "-") -> 7.875
A9: Cooper Ridley (Sr) | B9: =COUNTIF('Game Stats'!A:A, A9) -> 24 | C9: =D9+M9+O9+P9+Q9 -> 77 | D9: =sumif('Game Stats'!$A:$A, $A9, 'Game Stats'!B:B) -> 65 | E9: =sumif('Game Stats'!$A:$A, $A9, 'Game Stats'!C:C) -> 19 | F9: =sumif('Game Stats'!$A:$A, $A9, 'Game Stats'!D:D) -> 21 | G9: =sumif('Game Stats'!$A:$A, $A9, 'Game Stats'!E:E) -> 20 | H9: =F9-(I9+J9+K9) -> 11 | I9: =sumif('Game Stats'!$A:$A, $A9, 'Game Stats'!G:G) -> 3 | J9: =sumif('Game Stats'!$A:$A, $A9, 'Game Stats'!H:H) -> 4 | K9: =sumif('Game Stats'!$A:$A, $A9, 'Game Stats'!I:I) -> 3 | L9: =sumif('Game Stats'!$A:$A, $A9, 'Game Stats'!Q:Q) -> 13 | M9: =sumif('Game Stats'!$A:$A, $A9, 'Game Stats'!J:J) -> 11 | N9: =sumif('Game Stats'!$A:$A, $A9, 'Game Stats'!K:K) -> 22 | O9: =sumif('Game Stats'!$A:$A, $A9, 'Game Stats'!N:N) -> 1 | P9: =sumif('Game Stats'!$A:$A, $A9, 'Game Stats'!L:L) -> 0 | Q9: =sumif('Game Stats'!$A:$A, $A9, 'Game Stats'!M:M) -> 0 | R9: =(H9+(2*I9)+(3*J9)+(4*K9)) -> 41 | S9: =iferror(if(C9=0,"-", F9/D9), 0) -> 0.32307692 | T9: =if(C9=0, "-", (F9+M9+O9)/(D9+M9+O9+P9)) -> 0.42857143 | U9: =iferror(if(C9=0, "-", R9/D9), 0) -> 0.63076923 | V9: =if(T9="-", "-", T9+U9) -> 1.0593407 | W9: =if(D9=0,"-", ((F9+M9)*R9)/(D9+M9)) -> 17.263158 | X9: =if(C9=0, "-", M9/C9) -> 0.14285714 | Y9: =if(C9=0, "-", N9/C9) -> 0.28571429 | Z9: =ifs(Y9="-", "-", Y9=0, "0", Y9<>0, M9/N9) -> 0.5 | AA9: =IF(K9=0, "-", D9/K9) -> 21.666667 | AB9: =if(C9=0, "-", ((0.69*M9)+(0.72*O9)+(0.88*H9)+(1.24*I9)+(1.57*J9)+(2*K9))/(D9+M9+O9+P9)) -> 0.44142857 | AC9: =if(D9=0, "-", sumif('Game Stats'!AD:AD, A9, 'Game Stats'!AC:AC)) -> 11 | AD9: 1 | AE9: =if(L9=0, "-", L9/(L9+AD9)) -> 0.92857143 | AF9: 0 | AG9: =iferror((F9-K9)/(D9-K9-N9+P9), "-") -> 0.45 | AH9: =iferror((R9-F9)/D9, "-") -> 0.30769231 | AI9: =iferror(2*(K9*L9)/(K9+L9), "-") -> 4.875
A10: Donovan Glosser (So) | B10: =COUNTIF('Game Stats'!A:A, A10) -> 18 | C10: =D10+M10+O10+P10+Q10 -> 50 | D10: =sumif('Game Stats'!$A:$A, $A10, 'Game Stats'!B:B) -> 37 | E10: =sumif('Game Stats'!$A:$A, $A10, 'Game Stats'!C:C) -> 9 | F10: =sumif('Game Stats'!$A:$A, $A10, 'Game Stats'!D:D) -> 7 | G10: =sumif('Game Stats'!$A:$A, $A10, 'Game Stats'!E:E) -> 5 | H10: =F10-(I10+J10+K10) -> 6 | I10: =sumif('Game Stats'!$A:$A, $A10, 'Game Stats'!G:G) -> 1 | J10: =sumif('Game Stats'!$A:$A, $A10, 'Game Stats'!H:H) -> 0 | K10: =sumif('Game Stats'!$A:$A, $A10, 'Game Stats'!I:I) -> 0 | L10: =sumif('Game Stats'!$A:$A, $A10, 'Game Stats'!Q:Q) -> 8 | M10: =sumif('Game Stats'!$A:$A, $A10, 'Game Stats'!J:J) -> 10 | N10: =sumif('Game Stats'!$A:$A, $A10, 'Game Stats'!K:K) -> 10 | O10: =sumif('Game Stats'!$A:$A, $A10, 'Game Stats'!N:N) -> 1 | P10: =sumif('Game Stats'!$A:$A, $A10, 'Game Stats'!L:L) -> 0 | Q10: =sumif('Game Stats'!$A:$A, $A10, 'Game Stats'!M:M) -> 2 | R10: =(H10+(2*I10)+(3*J10)+(4*K10)) -> 8 | S10: =iferror(if(C10=0,"-", F10/D10), 0) -> 0.18918919 | T10: =if(C10=0, "-", (F10+M10+O10)/(D10+M10+O10+P10)) -> 0.375 | U10: =iferror(if(C10=0, "-", R10/D10), 0) -> 0.21621622 | V10: =if(T10="-", "-", T10+U10) -> 0.59121622 | W10: =if(D10=0,"-", ((F10+M10)*R10)/(D10+M10)) -> 2.893617 | X10: =if(C10=0, "-", M10/C10) -> 0.2 | Y10: =if(C10=0, "-", N10/C10) -> 0.2 | Z10: =ifs(Y10="-", "-", Y10=0, "0", Y10<>0, M10/N10) -> 1 | AA10: =IF(K10=0, "-", D10/K10) -> - | AB10: =if(C10=0, "-", ((0.69*M10)+(0.72*O10)+(0.88*H10)+(1.24*I10)+(1.57*J10)+(2*K10))/(D10+M10+O10+P10)) -> 0.29458333 | AC10: =if(D10=0, "-", sumif('Game Stats'!AD:AD, A10, 'Game Stats'!AC:AC)) -> 6 | AD10: 0 | AE10: =if(L10=0, "-", L10/(L10+AD10)) -> 1 | AF10: 1 | AG10: =iferror((F10-K10)/(D10-K10-N10+P10), "-") -> 0.25925926 | AH10: =iferror((R10-F10)/D10, "-") -> 0.027027027 | AI10: =iferror(2*(K10*L10)/(K10+L10), "-") -> 0
A11: Griffin Booth (Sr) | B11: =COUNTIF('Game Stats'!A:A, A11) -> 9 | C11: =D11+M11+O11+P11+Q11 -> 24 | D11: =sumif('Game Stats'!$A:$A, $A11, 'Game Stats'!B:B) -> 18 | E11: =sumif('Game Stats'!$A:$A, $A11, 'Game Stats'!C:C) -> 5 | F11: =sumif('Game Stats'!$A:$A, $A11, 'Game Stats'!D:D) -> 3 | G11: =sumif('Game Stats'!$A:$A, $A11, 'Game Stats'!E:E) -> 3 | H11: =F11-(I11+J11+K11) -> 2 | I11: =sumif('Game Stats'!$A:$A, $A11, 'Game Stats'!G:G) -> 1 | J11: =sumif('Game Stats'!$A:$A, $A11, 'Game Stats'!H:H) -> 0 | K11: =sumif('Game Stats'!$A:$A, $A11, 'Game Stats'!I:I) -> 0 | L11: =sumif('Game Stats'!$A:$A, $A11, 'Game Stats'!Q:Q) -> 0 | M11: =sumif('Game Stats'!$A:$A, $A11, 'Game Stats'!J:J) -> 4 | N11: =sumif('Game Stats'!$A:$A, $A11, 'Game Stats'!K:K) -> 4 | O11: =sumif('Game Stats'!$A:$A, $A11, 'Game Stats'!N:N) -> 0 | P11: =sumif('Game Stats'!$A:$A, $A11, 'Game Stats'!L:L) -> 0 | Q11: =sumif('Game Stats'!$A:$A, $A11, 'Game Stats'!M:M) -> 2 | R11: =(H11+(2*I11)+(3*J11)+(4*K11)) -> 4 | S11: =iferror(if(C11=0,"-", F11/D11), 0) -> 0.16666667 | T11: =if(C11=0, "-", (F11+M11+O11)/(D11+M11+O11+P11)) -> 0.31818182 | U11: =iferror(if(C11=0, "-", R11/D11), 0) -> 0.22222222 | V11: =if(T11="-", "-", T11+U11) -> 0.54040404 | W11: =if(D11=0,"-", ((F11+M11)*R11)/(D11+M11)) -> 1.2727273 | X11: =if(C11=0, "-", M11/C11) -> 0.16666667 | Y11: =if(C11=0, "-", N11/C11) -> 0.16666667 | Z11: =ifs(Y11="-", "-", Y11=0, "0", Y11<>0, M11/N11) -> 1 | AA11: =IF(K11=0, "-", D11/K11) -> - | AB11: =if(C11=0, "-", ((0.69*M11)+(0.72*O11)+(0.88*H11)+(1.24*I11)+(1.57*J11)+(2*K11))/(D11+M11+O11+P11)) -> 0.26181818 | AC11: =if(D11=0, "-", sumif('Game Stats'!AD:AD, A11, 'Game Stats'!AC:AC)) -> 2 | AD11: 0 | AE11: =if(L11=0, "-", L11/(L11+AD11)) -> - | AF11: 1 | AG11: =iferror((F11-K11)/(D11-K11-N11+P11), "-") -> 0.21428571 | AH11: =iferror((R11-F11)/D11, "-") -> 0.055555556 | AI11: =iferror(2*(K11*L11)/(K11+L11), "-") -> -
A12: Jackson Porta (Sr) | B12: =COUNTIF('Game Stats'!A:A, A12) -> 23 | C12: =D12+M12+O12+P12+Q12 -> 68 | D12: =sumif('Game Stats'!$A:$A, $A12, 'Game Stats'!B:B) -> 57 | E12: =sumif('Game Stats'!$A:$A, $A12, 'Game Stats'!C:C) -> 11 | F12: =sumif('Game Stats'!$A:$A, $A12, 'Game Stats'!D:D) -> 16 | G12: =sumif('Game Stats'!$A:$A, $A12, 'Game Stats'!E:E) -> 16 | H12: =F12-(I12+J12+K12) -> 10 | I12: =sumif('Game Stats'!$A:$A, $A12, 'Game Stats'!G:G) -> 5 | J12: =sumif('Game Stats'!$A:$A, $A12, 'Game Stats'!H:H) -> 1 | K12: =sumif('Game Stats'!$A:$A, $A12, 'Game Stats'!I:I) -> 0 | L12: =sumif('Game Stats'!$A:$A, $A12, 'Game Stats'!Q:Q) -> 10 | M12: =sumif('Game Stats'!$A:$A, $A12, 'Game Stats'!J:J) -> 9 | N12: =sumif('Game Stats'!$A:$A, $A12, 'Game Stats'!K:K) -> 11 | O12: =sumif('Game Stats'!$A:$A, $A12, 'Game Stats'!N:N) -> 0 | P12: =sumif('Game Stats'!$A:$A, $A12, 'Game Stats'!L:L) -> 2 | Q12: =sumif('Game Stats'!$A:$A, $A12, 'Game Stats'!M:M) -> 0 | R12: =(H12+(2*I12)+(3*J12)+(4*K12)) -> 23 | S12: =iferror(if(C12=0,"-", F12/D12), 0) -> 0.28070175 | T12: =if(C12=0, "-", (F12+M12+O12)/(D12+M12+O12+P12)) -> 0.36764706 | U12: =iferror(if(C12=0, "-", R12/D12), 0) -> 0.40350877 | V12: =if(T12="-", "-", T12+U12) -> 0.77115583 | W12: =if(D12=0,"-", ((F12+M12)*R12)/(D12+M12)) -> 8.7121212 | X12: =if(C12=0, "-", M12/C12) -> 0.13235294 | Y12: =if(C12=0, "-", N12/C12) -> 0.16176471 | Z12: =ifs(Y12="-", "-", Y12=0, "0", Y12<>0, M12/N12) -> 0.81818182 | AA12: =IF(K12=0, "-", D12/K12) -> - | AB12: =if(C12=0, "-", ((0.69*M12)+(0.72*O12)+(0.88*H12)+(1.24*I12)+(1.57*J12)+(2*K12))/(D12+M12+O12+P12)) -> 0.335 | AC12: =if(D12=0, "-", sumif('Game Stats'!AD:AD, A12, 'Game Stats'!AC:AC)) -> 16 | AD12: 1 | AE12: =if(L12=0, "-", L12/(L12+AD12)) -> 0.90909091 | AF12: 0 | AG12: =iferror((F12-K12)/(D12-K12-N12+P12), "-") -> 0.33333333 | AH12: =iferror((R12-F12)/D12, "-") -> 0.12280702 | AI12: =iferror(2*(K12*L12)/(K12+L12), "-") -> 0
A13: Jake Bell (Sr) | B13: =COUNTIF('Game Stats'!A:A, A13) -> 14 | C13: =D13+M13+O13+P13+Q13 -> 42 | D13: =sumif('Game Stats'!$A:$A, $A13, 'Game Stats'!B:B) -> 28 | E13: =sumif('Game Stats'!$A:$A, $A13, 'Game Stats'!C:C) -> 12 | F13: =sumif('Game Stats'!$A:$A, $A13, 'Game Stats'!D:D) -> 10 | G13: =sumif('Game Stats'!$A:$A, $A13, 'Game Stats'!E:E) -> 6 | H13: =F13-(I13+J13+K13) -> 7 | I13: =sumif('Game Stats'!$A:$A, $A13, 'Game Stats'!G:G) -> 2 | J13: =sumif('Game Stats'!$A:$A, $A13, 'Game Stats'!H:H) -> 1 | K13: =sumif('Game Stats'!$A:$A, $A13, 'Game Stats'!I:I) -> 0 | L13: =sumif('Game Stats'!$A:$A, $A13, 'Game Stats'!Q:Q) -> 5 | M13: =sumif('Game Stats'!$A:$A, $A13, 'Game Stats'!J:J) -> 9 | N13: =sumif('Game Stats'!$A:$A, $A13, 'Game Stats'!K:K) -> 9 | O13: =sumif('Game Stats'!$A:$A, $A13, 'Game Stats'!N:N) -> 1 | P13: =sumif('Game Stats'!$A:$A, $A13, 'Game Stats'!L:L) -> 0 | Q13: =sumif('Game Stats'!$A:$A, $A13, 'Game Stats'!M:M) -> 4 | R13: =(H13+(2*I13)+(3*J13)+(4*K13)) -> 14 | S13: =iferror(if(C13=0,"-", F13/D13), 0) -> 0.35714286 | T13: =if(C13=0, "-", (F13+M13+O13)/(D13+M13+O13+P13)) -> 0.52631579 | U13: =iferror(if(C13=0, "-", R13/D13), 0) -> 0.5 | V13: =if(T13="-", "-", T13+U13) -> 1.0263158 | W13: =if(D13=0,"-", ((F13+M13)*R13)/(D13+M13)) -> 7.1891892 | X13: =if(C13=0, "-", M13/C13) -> 0.21428571 | Y13: =if(C13=0, "-", N13/C13) -> 0.21428571 | Z13: =ifs(Y13="-", "-", Y13=0, "0", Y13<>0, M13/N13) -> 1 | AA13: =IF(K13=0, "-", D13/K13) -> - | AB13: =if(C13=0, "-", ((0.69*M13)+(0.72*O13)+(0.88*H13)+(1.24*I13)+(1.57*J13)+(2*K13))/(D13+M13+O13+P13)) -> 0.45105263 | AC13: =if(D13=0, "-", sumif('Game Stats'!AD:AD, A13, 'Game Stats'!AC:AC)) -> 9 | AD13: 0 | AE13: =if(L13=0, "-", L13/(L13+AD13)) -> 1 | AF13: 1 | AG13: =iferror((F13-K13)/(D13-K13-N13+P13), "-") -> 0.52631579 | AH13: =iferror((R13-F13)/D13, "-") -> 0.14285714 | AI13: =iferror(2*(K13*L13)/(K13+L13), "-") -> 0
A14: Jovan Love (Sr) | B14: =COUNTIF('Game Stats'!A:A, A14) -> 22 | C14: =D14+M14+O14+P14+Q14 -> 74 | D14: =sumif('Game Stats'!$A:$A, $A14, 'Game Stats'!B:B) -> 56 | E14: =sumif('Game Stats'!$A:$A, $A14, 'Game Stats'!C:C) -> 25 | F14: =sumif('Game Stats'!$A:$A, $A14, 'Game Stats'!D:D) -> 22 | G14: =sumif('Game Stats'!$A:$A, $A14, 'Game Stats'!E:E) -> 20 | H14: =F14-(I14+J14+K14) -> 14 | I14: =sumif('Game Stats'!$A:$A, $A14, 'Game Stats'!G:G) -> 4 | J14: =sumif('Game Stats'!$A:$A, $A14, 'Game Stats'!H:H) -> 0 | K14: =sumif('Game Stats'!$A:$A, $A14, 'Game Stats'!I:I) -> 4 | L14: =sumif('Game Stats'!$A:$A, $A14, 'Game Stats'!Q:Q) -> 15 | M14: =sumif('Game Stats'!$A:$A, $A14, 'Game Stats'!J:J) -> 12 | N14: =sumif('Game Stats'!$A:$A, $A14, 'Game Stats'!K:K) -> 15 | O14: =sumif('Game Stats'!$A:$A, $A14, 'Game Stats'!N:N) -> 3 | P14: =sumif('Game Stats'!$A:$A, $A14, 'Game Stats'!L:L) -> 3 | Q14: =sumif('Game Stats'!$A:$A, $A14, 'Game Stats'!M:M) -> 0 | R14: =(H14+(2*I14)+(3*J14)+(4*K14)) -> 38 | S14: =iferror(if(C14=0,"-", F14/D14), 0) -> 0.39285714 | T14: =if(C14=0, "-", (F14+M14+O14)/(D14+M14+O14+P14)) -> 0.5 | U14: =iferror(if(C14=0, "-", R14/D14), 0) -> 0.67857143 | V14: =if(T14="-", "-", T14+U14) -> 1.1785714 | W14: =if(D14=0,"-", ((F14+M14)*R14)/(D14+M14)) -> 19 | X14: =if(C14=0, "-", M14/C14) -> 0.16216216 | Y14: =if(C14=0, "-", N14/C14) -> 0.2027027 | Z14: =ifs(Y14="-", "-", Y14=0, "0", Y14<>0, M14/N14) -> 0.8 | AA14: =IF(K14=0, "-", D14/K14) -> 14 | AB14: =if(C14=0, "-", ((0.69*M14)+(0.72*O14)+(0.88*H14)+(1.24*I14)+(1.57*J14)+(2*K14))/(D14+M14+O14+P14)) -> 0.4827027 | AC14: =if(D14=0, "-", sumif('Game Stats'!AD:AD, A14, 'Game Stats'!AC:AC)) -> 16 | AD14: 0 | AE14: =if(L14=0, "-", L14/(L14+AD14)) -> 1 | AF14: 1 | AG14: =iferror((F14-K14)/(D14-K14-N14+P14), "-") -> 0.45 | AH14: =iferror((R14-F14)/D14, "-") -> 0.28571429 | AI14: =iferror(2*(K14*L14)/(K14+L14), "-") -> 6.3157895
